<?xml version="1.0" ?>
<!-- =================================================================================== -->
<!-- |    This document was autogenerated by xacro from underwater_snakerobot.urdf.xacro | -->
<!-- |    EDITING THIS FILE BY HAND IS NOT RECOMMENDED                                 | -->
<!-- =================================================================================== -->
<robot name="underwater_snakerobot_description" xmlns:xacro="http://www.ros.org/wiki/xacro">
  <!---............................. Link Definitions ................................-->
  <link name="base_link">
    <inertial>
      <mass value="2"/>
      <inertia ixx="2" ixy="0" ixz="0" iyy="2" iyz="0" izz="0.0144"/>
    </inertial>
    <visual>
      <origin rpy="3.141592654 0 -1.570796327" xyz="0.0 0.0 0.0"/>
      <geometry>
        <mesh filename="/home/michael/catkin_ws/src/underwater_simulation/underwater_snakerobot_description/meshes/body_2links_head-blender.osg"/>
      </geometry>
    </visual>
  </link>
  <link name="screw_1_left">
    <visual>
      <origin rpy="-3.141592654 0 1.570796327" xyz="0.0 0.0 0.0"/>
      <geometry>
        <mesh filename="/home/michael/catkin_ws/src/underwater_simulation/underwater_snakerobot_description/meshes/screw_left_CFD-blender.osg"/>
      </geometry>
    </visual>
  </link>
  <link name="screw_1_right">
    <visual>
      <origin rpy="0 4.712388981 0" xyz="-0.0 0.0 0.0"/>
      <geometry>
        <mesh filename="/home/michael/catkin_ws/src/underwater_simulation/underwater_snakerobot_description/meshes/screw_right_CFD.osg"/>
      </geometry>
    </visual>
  </link>
  <link name="link_2">
    <inertial>
      <mass value="2"/>
      <inertia ixx="2" ixy="0" ixz="0" iyy="2" iyz="0" izz="0.0144"/>
    </inertial>
    <visual>
      <origin rpy="0 0 0" xyz="0.0 0.0 0.0"/>
      <geometry>
        <mesh filename="/home/michael/catkin_ws/src/underwater_simulation/underwater_snakerobot_description/meshes/body_2links.osg"/>
      </geometry>
    </visual>
  </link>
  <link name="screw_2_left">
    <visual>
      <origin rpy="0 4.712388981 0" xyz="0.0 0.0 0.0"/>
      <geometry>
        <mesh filename="/home/michael/catkin_ws/src/underwater_simulation/underwater_snakerobot_description/meshes/screw_left_CFD.osg"/>
      </geometry>
    </visual>
  </link>
  <link name="screw_2_right">
    <visual>
      <origin rpy="0 -1.570796327 0" xyz="-0.0 0.0 0.0"/>
      <geometry>
        <mesh filename="/home/michael/catkin_ws/src/underwater_simulation/underwater_snakerobot_description/meshes/screw_right_CFD.osg"/>
      </geometry>
    </visual>
  </link>
  <!--...........................Joint Definitions.....................................-->
  <joint name="base_link_to_screw_1_left_joint" type="continuous">
    <parent link="base_link"/>
    <child link="screw_1_left"/>
    <origin rpy="0 3.141592654 0" xyz="0.181 0 0"/>
    <limit effort="1000.0" lower="-inf" upper="inf" velocity="10.0"/>
    <safety_controller k_position="5" k_velocity="10"/>
  </joint>
  <joint name="base_link_to_screw_1_right_joint" type="continuous">
    <parent link="base_link"/>
    <child link="screw_1_right"/>
    <origin rpy="0 0 0" xyz="0.117 0 0"/>
    <limit effort="1000.0" lower="-inf" upper="inf" velocity="10.0"/>
    <safety_controller k_position="5" k_velocity="10"/>
  </joint>
  <joint name="base_link_to_link_2" type="continuous">
    <parent link="base_link"/>
    <child link="link_2"/>
    <origin rpy="0 -1.570796327 0" xyz="0 0 0.0"/>
    <limit effort="100.0" lower="-1.0" upper="1.0" velocity="10.0"/>
    <safety_controller k_position="20" k_velocity="20"/>
  </joint>
  <joint name="link_2_to_screw_2_left_joint" type="continuous">
    <parent link="link_2"/>
    <child link="screw_2_left"/>
    <origin rpy="0 4.712388981 0" xyz="0 0 0.117"/>
    <limit effort="1000.0" lower="-inf" upper="inf" velocity="10.0"/>
    <safety_controller k_position="5" k_velocity="5"/>
  </joint>
  <joint name="link_2_to_screw_2_right_joint" type="continuous">
    <parent link="link_2"/>
    <child link="screw_2_right"/>
    <origin rpy="0 1.570796327 0" xyz="0 0 0.181"/>
    <limit effort="1000.0" lower="-inf" upper="inf" velocity="10.0"/>
    <safety_controller k_position="5" k_velocity="5"/>
  </joint>
</robot>
